Workbook

Sheet Leia-me
A1: Projeção Financeira 5 Anos — Neural Day Trader
A2: Reconstruída em 2026-08-10 a partir dos preços REAIS da landing page. Não existia arquivo rastreável anterior no repositório — a versão citada em PLANEJAMENTO-LANCAMENTO-NEURAL-DAY-TRADER.md era só um resumo em texto de uma sessão de planejamento (11/07/2026), nunca uma planilha auditável.
A4: Como usar
A5: Células em AZUL são premissas editáveis — mude-as na aba 'Premissas' e todo o resto recalcula.
A6: Células em PRETO são fórmulas — não editar diretamente, elas recalculam sozinhas.
A7: Células em VERDE são links pra outra aba (ex: Resumo Anual puxando das abas de cenário).
A8: Fundo AMARELO marca a premissa mais sensível de cada bloco — a que mais muda o resultado se você testar cenários.
A10: Estrutura do arquivo
A11: • Premissas — todos os inputs dos 3 cenários lado a lado, com a fonte/base de cada número.
A12: • Pessimista / Realista / Otimista — modelo mês a mês (mês 0 a mês 60 = 5 anos completos), 100% fórmula.
A13: • Resumo Anual — os 3 cenários consolidados por Ano 1..5, lado a lado, pra comparação rápida.
A14: • Comissionamento — proposta de modelo de comissão realinhada com prática de mercado (ver pergunta do Cleber).
... A22: Recalcule sempre que houver dado real de conversão/churn dos primeiros usuários pagantes — substitua a premissa por medição real assim que existir (mesma disciplina do resto do projeto: CostModel.ts recalibra assim que há execução real medida).

Sheet Premissas
A1: Premissas do Modelo Financeiro — 3 Cenários
A3: Premissa | B3: Pessimista | C3: Realista | D3: Otimista | E3: Fonte / base do número | F3: Bootstrap (sem CAC pago) | G3: Fonte / base do número — Bootstrap (só onde difere do Realista)
A4: ── PREÇOS (medidos — landing page) ──
A5: Preço mensalidade Node: Pro (R$/mês) | B5: 199 | C5: 199 | D5: 199 | E5: MEDIDO. translations.ts:114 — 'Node: Pro', price: 'R$199,00'. Igual nos 3 cenários (preço da landing não varia por cenário de crescimento). | F5: 199
A6: Preço mensalidade Node: Institutional (R$/mês) | B6: 399 | C6: 399 | D6: 399 | E6: MEDIDO. translations.ts:121 — 'Node: Institutional', price: 'R$399,00'. | F6: 399
A8: ── FUNIL (premissa — sem dado real, produto não lançado) ──
A9: Novos cadastros Starter no mês 1 (qtd) | B9: 40 | C9: 80 | D9: 150 | E9: PREMISSA. Ordem de grandeza herdada do plano de 11/07 (5-25 pess / 10-80 real / 25-200 otim novos usuários/mês), mas agora como TOPO de funil (cadastro grátis), não usuário pagante direto. | F9: 20 | G9: NOVO 2026-09-07. Sem CAC pago, o volume de cadastros vem só de orgânico/indicação — estimativa mais baixa que os outros cenários (que já assumem mídia paga desde o mês 1). PREMISSA/julgamento, não medição — produto não lançado.
A10: Crescimento mensal de novos cadastros (%) | B10: 0.02 | C10: 0.045 | D10: 0.08 | E10: PREMISSA — decisão de modelagem p/ atender pedido de 'crescimento exponencial': crescimento composto mês a mês em vez do ritmo linear do plano de 11/07. 2%/mês pessimista a 8%/mês otimista são faixas típicas de SaaS em tração inicial via marketing de performance + comunidade — não é medição, é meta de modelagem. | F10: 0.03 | G10: NOVO 2026-09-07. Crescimento só por indicação/boca-a-boca tende a ser mais lento que o puxado por mídia paga — usado 3%/mês, entre o Pessimista (2%) e o Realista (4,5%) da mídia paga, sem dado real por trás.
A11: Teto de novos cadastros/mês — saturação de mercado (qtd) | B11: 350 | C11: 900 | D11: 2200 | E11: ⚠️ CORREÇÃO — sem este teto, 8%/mês composto por 60 meses (Otimista) gerava >15.000 novos cadastros NO ÚLTIMO MÊS sozinho e R$217 milhões de faturamento em 5 anos — matematicamente correto, mas fora de qualquer mercado real pro nicho (trading de varejo automatizado no Brasil). PREMISSA de bom senso, não medição: ordem de grandeza de TAM plausível pro nicho, crescimento composto se aplica só até bater o teto, depois estabiliza. Recalibrar assim que houver dado real de mercado endereçável (tamanho da base de traders de varejo ativos no Brasil que operam MT5/CFD). | F11: 500
A12: Taxa de conversão Starter → Pago (%, defasagem de 2 meses) | B12: 0.03 | C12: 0.08 | D12: 0.11 | E12: PREMISSA. Benchmark de mercado p/ SaaS freemium com valor demonstrável rápido costuma ficar 2-5% (free→paid); o realista já usava o topo dessa faixa (Starter entrega sinal validado de verdade, não 'feature capada'). ⚠️ AJUSTADO 2026-08-10: Realista 6%→8% — acima do benchmark genérico de SaaS, assume gatilho de conversão orientado por produto (ver aba 'Sugestões de Crescimento' item 2: prompt no momento exato de dor — sinal que teria sido lucrativo mas não pôde executar automático), não só tempo de uso passivo. Requer instrumentar esse gatilho antes do lançamento pra sustentar — se não for construído, volte pra 6%. Pessimista mantido em 3% de propósito: representa o cenário sem esse gatilho funcionando. | F12: 0.08
A13: Mix Pro entre novos pagantes (%) [resto vai pra Institutional] | B13: 0.9 | C13: 0.75 | D13: 0.55 | E13: PREMISSA. Reaproveita o mix Pro/Institutional já usado na correção de 2026-08-10 do plano de 11/07 (PLANEJAMENTO-LANCAMENTO-NEURAL-DAY-TRADER.md §3.1) — Institutional tem selo 'Recommended' na landing, então a fração de Institutional cresce nos cenários mais otimistas de captação qualificada. | F13: 0.75
A14: Churn mensal Node: Starter — abandono do cadastro grátis (%) | B14: 0.15 | C14: 0.12 | D14: 0.09 | E14: PREMISSA. Free tier tem churn/abandono normalmente mais alto que tier pago (sem fricção de cancelamento, sem sunk cost) — faixa 9-15%/mês é conservadora pro setor de ferramentas de trading. | F14: 0.12
A15: Churn mensal Pago (Pro + Institutional) (%) | B15: 0.08 | C15: 0.06 | D15: 0.04 | E15: PREMISSA. Plano de 11/07 já assumia 8%/6%/4% pess/real/otim (mesma linha, mantida) — nota do próprio plano: 'pessimista honesto seria 12-15%/mês' pro varejo de trading em geral; mantemos a faixa original por ainda não termos dado de retenção real do produto pago. | F15: 0.06
A17: ── VOLUME DE OPERAÇÃO (premissa) ──
A18: Lotes negociados/mês por usuário Pago | B18: 2.5 | C18: 5 | D18: 8.5 | E18: PREMISSA. Sem dado de execução real ainda (o runner 24/7 está em telemetria, 0 trades reais até 08-10 — ver NEXT_SESSION.md). Ordem de grandeza de um trader ativo de varejo intraday/swing operando com disciplina (poucos lotes, não overtrading) — deliberadamente conservador. | F18: 5
A19: Lotes negociados/mês por usuário Starter (execução manual) | B19: 0.3 | C19: 0.7 | D19: 1.2 | E19: ⚠️ REINTERPRETADO 2026-09-07: com a mudança de produto (Starter roda o motor autônomo até um limite de operações, depois corta — ver linhas 37-38), este número deixa de ser 'lotes/mês em uso contínuo' e passa a ser o TOTAL de lotes negociados durante a degustação inteira (evento único por cadastro novo, não recorrente todo mês). Valor mantido (0,3/0,7/1,2) por ser a mesma ordem de grandeza já estimada — ainda PREMISSA, sem medição real de quanto volume 10-30 operações reais geram em lotes. | F19: 0.7
A21: ── COMISSÃO E REBATE (ver aba 'Comissionamento' p/ a proposta completa) ──
A22: Comissão própria por lote — cobrada em TODOS os tiers (R$) | B22: 40 | C22: 40 | D22: 40 | E22: DECISÃO DE MODELO realinhada com mercado — ver aba Comissionamento. Cobrada sobre todo o volume operado, Starter + Pro + Institutional (decisão explícita do Cleber em 2026-08-10). ⚠️ AJUSTADO 2026-08-10 (2ª correção, mesma sessão): R$30→R$40/lote (≈US$8/lote) — ainda dentro do benchmark cTrader ECN (US$4-8/lote) citado no plano de 11/07, agora no teto da faixa em vez do meio, como parte do pacote de alavancas pra alcançar lucro no Ano 1 (pedido do Cleber — ver aba Comissionamento §'Plano de lucro Ano 1'). Igual nos 3 cenários — é política de preço. | F22: 40
A23: Rebate IB por lote — já convertido em R$ (R$/lote) | B23: 25 | C23: 35 | D23: 45 | E23: PREMISSA ancorada em research anterior do projeto (PLANEJAMENTO-LANCAMENTO §3: rebate IB US$4/6/8 por lote, INFINOX Partners paga até US$20/lote) convertido a ~R$5,05/US$1. ⚠️ AJUSTADO 2026-08-10: +R$10/lote em cada cenário (R$15/25/35 → R$25/35/45) — assume negociação de rebate mais agressiva com a corretora desde o lançamento (ainda abaixo do teto de US$20/lote que a Infinox Partners paga pra parceiros com volume) — parte do pacote pra lucro no Ano 1. Requer negociação real com a corretora antes do lançamento, não é automático. | F23: 35
A24: Receita marketplace líquida por usuário Pago/mês (R$) | B24: 3.5 | C24: 7.5 | D24: 13 | E24: PREMISSA. Mesma base do plano de 11/07 (US$0,50-2,00 líquido/usuário/mês, MQL5 retém ~25%), convertida a R$ e só aplicada sobre usuários pagantes (Starter não tem acesso ao catálogo completo — translations.ts:110 vs 124). | F24: 7.5
A26: ── CUSTOS (premissa/orçamento) ──
A27: CAC — custo de aquisição por novo cadastro (R$) | B27: 90 | C27: 110 | D27: 130 | E27: PREMISSA. Plano de 11/07 §4 furo #2 já alertava 'aquisição em trading de varejo custa R$100-400/usuário' — aplicado sobre CADASTROS (topo de funil), não só pagantes, porque o CAC é pago no clique/lead, converta ou não. ⚠️ AJUSTADO 2026-08-10: R$180/220/260 → R$90/110/130 (metade) — CAC era o maior custo isolado do Ano 1 (46% das despesas no cenário Realista original). A redução assume migrar aquisição de mídia paga pura pra um mix mais barato: comunidade/conteúdo educacional + programa de indicação entre usuários pagantes (ver aba 'Sugestões de Crescimento', item 5) — EXECUÇÃO REAL necessária pra sustentar esse número, não acontece sozinho. Se a aquisição ficar só em mídia paga, volte pro valor original (R$180-260). | F27: 0 | G27: NOVO 2026-09-07, decisão do Cleber: cenário hipotético onde a plataforma cresce só por orgânico/indicação, sem gastar em aquisição paga — é o corte que mais reduz a despesa do mês 1 (CAC sozinho era ~45% da despesa do mês 1 no Realista).
A28: Custo de infraestrutura por usuário ativo total/mês (R$) | B28: 80 | C28: 70 | D28: 45 | E28: ⚠️ SUPERADO 2026-09-07 pelo modelo em degrau (linhas 35-36 abaixo) — as fórmulas das abas de cenário (linha 27) NÃO usam mais este valor, foram reescritas pra CEILING(usuários pagantes / capacidade por GPU) × custo por GPU, que reflete economia de escala de verdade mês a mês. Este número (R$80/70/45) fica só como MÉDIA DE REFERÊNCIA — útil pra conversa rápida ('quanto custa por usuário, em média'), não é mais o que o modelo calcula.
A29: Pagantes por funcionário adicional (degrau de equipe) | B29: 700 | C29: 600 | D29: 450 | E29: PREMISSA. Plano de 11/07 §4 furo #2: '~1 pessoa por 300-500 usuários'. ⚠️ AJUSTADO 2026-08-10: degrau esticado (500/400/300 → 700/600/450) — atrasa a 1ª contratação além do fundador pra reduzir custo fixo no Ano 1, assumindo que suporte/onboarding inicial é feito pelo próprio Cleber até a base pagante justificar contratação. Recalibrar assim que a carga de suporte real exigir. | F29: 5000 | G29: NOVO 2026-09-07: linha 29 (pagantes por funcionário) fica sem efeito prático neste cenário porque a fórmula de custo de equipe usa ROUNDUP — qualquer pagante > 0 já arredonda pra 1 funcionário inteiro, não importa o divisor. O corte de verdade está na linha 30 (custo por funcionário = R$0 neste cenário).
A30: Custo mensal por funcionário (R$, CLT completo) | B30: 9000 | C30: 9000 | D30: 9000 | E30: PREMISSA — salário + encargos de um perfil suporte/CS júnior-pleno em SP, não pesquisado neste modelo (igual nos 3 cenários). Recalibrar com RH real antes de contratar. | F30: 0 | G30: NOVO 2026-09-07, a pedido do Cleber: cenário Bootstrap assume ele mesmo operando suporte/onboarding sem contratar (mesma premissa já registrada no texto original: 'suporte/onboarding inicial é feito pelo próprio Cleber até a base pagante justificar contratação'). Zerado pra refletir isso de fato nos 12 meses simulados — reavaliar quando a base pagante crescer o suficiente pra justificar a 1ª contratação de verdade.
A31: Custos fixos administrativos mensais (R$) — contador, ferramentas, jurídico recorrente | B31: 2000 | C31: 3000 | D31: 4000 | E31: PREMISSA ancorada no plano de 11/07 §1: 'Jurídico/contador R$3.000-6.000/ano recorrente' + parte do bloco de Segurança recorrente (R$0-1.200). ⚠️ AJUSTADO 2026-08-10: R$3.000/4.500/6.000 → R$2.000/3.000/4.000 — lançamento mais enxuto (contador simples + ferramentas essenciais, adiar gasto discricionário até o caixa permitir), parte do pacote de lucro no Ano 1. | F31: 3000
A32: Alíquota efetiva de imposto sobre faturamento — Simples Nacional (%) | B32: 0.07 | C32: 0.1 | D32: 0.135 | E32: PREMISSA ancorada no plano de 11/07 §4 furo #1: 'Simples ~6-15,5% do faturamento' — usamos o ponto baixo da faixa pro cenário de menor faturamento (Simples é progressivo por faixa de receita) e o ponto alto pro cenário de maior faturamento. | F32: 0.1
A33: Investimento inicial de lançamento (R$, saída no Mês 0) | B33: -21000 | C33: -21000 | D33: -21000 | E33: MEDIDO/citado no plano de 11/07 §1: 'Cenário enxuto (piloto controlado): ~R$21 mil'. Igual nos 3 cenários — o custo de lançar não muda com o cenário de tração pós-lançamento. | F33: -21000
A35: Custo mensal por GPU dedicada — serving com vLLM/batching (R$) | B35: 7400 | C35: 7400 | D35: 7400 | E35: REVISADO 2026-09-07. Base: aluguel de GPU A100 80GB em nuvem (RunPod/Lambda/CoreWeave, pesquisado ao vivo em 2026-09) ~US$1.400-1.500/mês rodando 24/7, convertido a ~R$5,12/USD (cotação de 2026-09-07) e arredondado. Escolha de GPU única (A100) em vez de opção mais barata pra manter margem de confiabilidade/redundância consistente nos 3 cenários — não varia por cenário porque é decisão de infraestrutura, não de crescimento de usuários. | F35: 7400
A36: Capacidade de usuários pagantes simultâneos por GPU (qtd) | B36: 150 | C36: 150 | D36: 150 | E36: REVISADO 2026-09-07. Baseado em throughput real medido do motor (vLLM com modelo 4-8B faria ~2.500 tokens/seg numa A100; carga medida de 30 usuários no cadência AGRESSIVA da cesta atual usa só ~15% dessa capacidade, 100 usuários ~50%). 150 é um teto conservador com folga de sobra pra picos de mercado — não é o limite físico da GPU (que seria mais alto), é uma escolha deliberadamente cautelosa antes de operar perto do limite real com dinheiro de cliente. | F36: 150
A37: Operações grátis do Starter antes de cortar (qtd) | B37: 30 | C37: 30 | D37: 30 | E37: NOVO 2026-09-07, decisão de produto do Cleber: Starter passa a rodar o motor autônomo de verdade (não só alerta manual) até completar este número de operações, depois corta — 'dar o gostinho' antes de exigir upgrade. Cleber considerou a faixa 10-30 e decidiu 30. Mesmo valor nos 3 cenários (é decisão de produto, não premissa de mercado). | F37: 30
A38: Duração média da degustação Starter até bater o limite (dias) | B38: 2 | C38: 2 | D38: 2 | E38: NOVO 2026-09-07. Estimativa do Cleber ('isso dá uns 2 dias de operação') baseada na cadência AGRESSIVA observada ao vivo no motor hoje. Usado só pra estimar a CARGA DE GPU da degustação (fração de um usuário-mês: 2/30 ≈ 6,7%), não define prazo de validade da conta Starter em si. | F38: 2
A39: Custo variável de infra via API por token, por usuário-mês equivalente (R$) | F39: 292 | G39: NOVO 2026-09-07. Base: pesquisa ao vivo de preço Groq/Nemotron (~US$1,90-2,10/usuário/dia sem cache de prompt, ver investigação de custo de 100 usuários desta sessão) × 30 dias × R$5,12/USD (cotação 2026-09-07) ≈ R$292/usuário-mês. Cruzamento com GPU dedicada (R$7.400/mês ÷ R$292 ≈ 25,3 usuários): abaixo de ~25 usuários-equivalentes, API paga sai mais barata que uma GPU ociosa; acima disso, GPU dedicada vence. O cenário Bootstrap usa o menor custo dos dois a cada mês (MIN), trocando de API pra GPU automaticamente quando a escala justificar.

Sheet Pessimista
A1: Cenário Pessimista — Projeção Mês a Mês (Lançamento + 60 meses = 5 anos)
A2: Todas as células desta aba são fórmula. Premissas (azul) ficam só na aba 'Premissas'.
A3: Métrica | B3: Unid. | C3: Lança- mento | D3: Ano 1 | P3: Ano 2 | AB3: Ano 3 | AN3: Ano 4 | AZ3: Ano 5
A4: ── FUNIL DE USUÁRIOS ── | C4: 0 | D4: 1 | E4: 2 | F4: 3 | G4: 4 | H4: 5 | I4: 6 | J4: 7 | K4: 8 | L4: 9 | M4: 10 | N4: 11 | O4: 12 | P4: 13 | Q4: 14 | R4: 15 | S4: 16 | T4: 17 | U4: 18 | V4: 19 | W4: 20 | X4: 21 | Y4: 22 | Z4: 23 | AA4: 24 | AB4: 25 | AC4: 26 | AD4: 27 | AE4: 28 | AF4: 29 | AG4: 30 | AH4: 31 | AI4: 32 | AJ4: 33 | AK4: 34 | AL4: 35 | AM4: 36 | AN4: 37 | AO4: 38 | AP4: 39 | AQ4: 40 | AR4: 41 | AS4: 42 | AT4: 43 | AU4: 44 | AV4: 45 | AW4: 46 | AX4: 47 | AY4: 48 | AZ4: 49 | BA4: 50 | BB4: 51 | BC4: 52 | BD4: 53 | BE4: 54 | BF4: 55 | BG4: 56 | BH4: 57 | BI4: 58 | BJ4: 59 | BK4: 60
A6: Novos cadastros Node: Starter (qtd) | B6: qtd | C6: 0 | D6: =MIN(Premissas!$B$9,Premissas!$B$11) | E6: =MIN(D6*(1+Premissas!$B$10),Premissas!$B$11) | F6: =MIN(E6*(1+Premissas!$B$10),Premissas!$B$11) | G6: =MIN(F6*(1+Premissas!$B$10),Premissas!$B$11) | H6: =MIN(G6*(1+Premissas!$B$10),Premissas!$B$11) | I6: =MIN(H6*(1+Premissas!$B$10),Premissas!$B$11) | J6: =MIN(I6*(1+Premissas!$B$10),Premissas!$B$11) | K6: =MIN(J6*(1+Premissas!$B$10),Premissas!$B$11) | L6: =MIN(K6*(1+Premissas!$B$10),Premissas!$B$11) | ... BK6: =MIN(BJ6*(1+Premissas!$B$10),Premissas!$B$11)
A7: Convertidos Starter → Pago no mês (qtd) | B7: qtd | C7: 0 | D7: 0 | E7: =C6*Premissas!$B$12 | F7: =D6*Premissas!$B$12 | G7: =E6*Premissas!$B$12 | H7: =F6*Premissas!$B$12 | I7: =G6*Premissas!$B$12 | J7: =H6*Premissas!$B$12 | K7: =I6*Premissas!$B$12 | L7: =J6*Premissas!$B$12 | ... BK7: =BI6*Premissas!$B$12
A8: Node: Starter ativos (qtd) | B8: qtd | C8: 0 | D8: =C8*(1-Premissas!$B$14)+D6-D7 | E8: =D8*(1-Premissas!$B$14)+E6-E7 | F8: =E8*(1-Premissas!$B$14)+F6-F7 | G8: =F8*(1-Premissas!$B$14)+G6-G7 | H8: =G8*(1-Premissas!$B$14)+H6-H7 | I8: =H8*(1-Premissas!$B$14)+I6-I7 | J8: =I8*(1-Premissas!$B$14)+J6-J7 | K8: =J8*(1-Premissas!$B$14)+K6-K7 | ... BK8: =BJ8*(1-Premissas!$B$14)+BK6-BK7
A9: Novos pagantes Node: Pro no mês (qtd) | B9: qtd | C9: 0 | D9: =D7*Premissas!$B$13 | E9: =E7*Premissas!$B$13 | F9: =F7*Premissas!$B$13 | G9: =G7*Premissas!$B$13 | H9: =H7*Premissas!$B$13 | I9: =I7*Premissas!$B$13 | J9: =J7*Premissas!$B$13 | K9: =K7*Premissas!$B$13 | ... BK9: =BK7*Premissas!$B$13
A10: Novos pagantes Node: Institutional no mês (qtd) | B10: qtd | C10: 0 | D10: =D7*(1-Premissas!$B$13) | E10: =E7*(1-Premissas!$B$13) | F10: =F7*(1-Premissas!$B$13) | G10: =G7*(1-Premissas!$B$13) | H10: =H7*(1-Premissas!$B$13) | I10: =I7*(1-Premissas!$B$13) | J10: =J7*(1-Premissas!$B$13) | K10: =K7*(1-Premissas!$B$13) | ... BK10: =BK7*(1-Premissas!$B$13)
A11: Node: Pro ativos (qtd) | B11: qtd | C11: 0 | D11: =C11*(1-Premissas!$B$15)+D9 | E11: =D11*(1-Premissas!$B$15)+E9 | F11: =E11*(1-Premissas!$B$15)+F9 | G11: =F11*(1-Premissas!$B$15)+G9 | H11: =G11*(1-Premissas!$B$15)+H9 | I11: =H11*(1-Premissas!$B$15)+I9 | J11: =I11*(1-Premissas!$B$15)+J9 | K11: =J11*(1-Premissas!$B$15)+K9 | ... BK11: =BJ11*(1-Premissas!$B$15)+BK9
A12: Node: Institutional ativos (qtd) | B12: qtd | C12: 0 | D12: =C12*(1-Premissas!$B$15)+D10 | E12: =D12*(1-Premissas!$B$15)+E10 | F12: =E12*(1-Premissas!$B$15)+F10 | G12: =F12*(1-Premissas!$B$15)+G10 | H12: =G12*(1-Premissas!$B$15)+H10 | I12: =H12*(1-Premissas!$B$15)+I10 | J12: =I12*(1-Premissas!$B$15)+J10 | K12: =J12*(1-Premissas!$B$15)+K10 | ... BK12: =BJ12*(1-Premissas!$B$15)+BK10
A13: Total pagantes ativos — Pro + Institutional (qtd) | B13: qtd | C13: 0 | D13: =D11+D12 | E13: =E11+E12 | F13: =F11+F12 | G13: =G11+G12 | H13: =H11+H12 | I13: =I11+I12 | J13: =J11+J12 | K13: =K11+K12 | ... BK13: =BK11+BK12
A14: Total usuários ativos — Starter + pagantes (qtd) | B14: qtd | C14: 0 | D14: =D8+D13 | E14: =E8+E13 | F14: =F8+F13 | G14: =G8+G13 | H14: =H8+H13 | I14: =I8+I13 | J14: =J8+J13 | K14: =K8+K13 | ... BK14: =BK8+BK13
A15: Carga de GPU equivalente (usuários-mês) — pagantes + degustação Starter | D15: =D13+D6*(Premissas!$B$38/30) | E15: =E13+E6*(Premissas!$B$38/30) | F15: =F13+F6*(Premissas!$B$38/30) | G15: =G13+G6*(Premissas!$B$38/30) | H15: =H13+H6*(Premissas!$B$38/30) | I15: =I13+I6*(Premissas!$B$38/30) | J15: =J13+J6*(Premissas!$B$38/30) | K15: =K13+K6*(Premissas!$B$38/30) | ... BK15: =BK13+BK6*(Premissas!$B$38/30)
A16: ── RECEITA ──
A17: Receita mensalidade Node: Pro (R$) | B17: R$ | C17: 0 | D17: =D11*Premissas!$B$5 | E17: =E11*Premissas!$B$5 | F17: =F11*Premissas!$B$5 | G17: =G11*Premissas!$B$5 | H17: =H11*Premissas!$B$5 | I17: =I11*Premissas!$B$5 | J17: =J11*Premissas!$B$5 | K17: =K11*Premissas!$B$5 | ... BK17: =BK11*Premissas!$B$5
A18: Receita mensalidade Node: Institutional (R$) | B18: R$ | C18: 0 | D18: =D12*Premissas!$B$6 | E18: =E12*Premissas!$B$6 | F18: =F12*Premissas!$B$6 | G18: =G12*Premissas!$B$6 | H18: =H12*Premissas!$B$6 | I18: =I12*Premissas!$B$6 | J18: =J12*Premissas!$B$6 | K18: =K12*Premissas!$B$6 | ... BK18: =BK12*Premissas!$B$6
A19: Lotes negociados no mês — Pro+Institutional (lotes) | B19: lotes | C19: 0 | D19: =D13*Premissas!$B$18 | E19: =E13*Premissas!$B$18 | F19: =F13*Premissas!$B$18 | G19: =G13*Premissas!$B$18 | H19: =H13*Premissas!$B$18 | I19: =I13*Premissas!$B$18 | J19: =J13*Premissas!$B$18 | K19: =K13*Premissas!$B$18 | ... BK19: =BK13*Premissas!$B$18
A20: Lotes negociados no mês — Starter (lotes) | B20: lotes | C20: 0 | D20: =D6*Premissas!$B$19 | E20: =E6*Premissas!$B$19 | F20: =F6*Premissas!$B$19 | G20: =G6*Premissas!$B$19 | H20: =H6*Premissas!$B$19 | I20: =I6*Premissas!$B$19 | J20: =J6*Premissas!$B$19 | K20: =K6*Premissas!$B$19 | ... BK20: =BK6*Premissas!$B$19
A21: Receita comissão própria — só sobre volume Starter (R$) | B21: R$ | C21: 0 | D21: =(D19+D20)*Premissas!$B$22 | E21: =(E19+E20)*Premissas!$B$22 | F21: =(F19+F20)*Premissas!$B$22 | G21: =(G19+G20)*Premissas!$B$22 | H21: =(H19+H20)*Premissas!$B$22 | I21: =(I19+I20)*Premissas!$B$22 | J21: =(J19+J20)*Premissas!$B$22 | K21: =(K19+K20)*Premissas!$B$22 | ... BK21: =(BK19+BK20)*Premissas!$B$22
A22: Receita rebate IB — sobre todo o volume (R$) | B22: R$ | C22: 0 | D22: =(D19+D20)*Premissas!$B$23 | E22: =(E19+E20)*Premissas!$B$23 | F22: =(F19+F20)*Premissas!$B$23 | G22: =(G19+G20)*Premissas!$B$23 | H22: =(H19+H20)*Premissas!$B$23 | I22: =(I19+I20)*Premissas!$B$23 | J22: =(J19+J20)*Premissas!$B$23 | K22: =(K19+K20)*Premissas!$B$23 | ... BK22: =(BK19+BK20)*Premissas!$B$23
A23: Receita marketplace (R$) | B23: R$ | C23: 0 | D23: =D13*Premissas!$B$24 | E23: =E13*Premissas!$B$24 | F23: =F13*Premissas!$B$24 | G23: =G13*Premissas!$B$24 | H23: =H13*Premissas!$B$24 | I23: =I13*Premissas!$B$24 | J23: =J13*Premissas!$B$24 | K23: =K13*Premissas!$B$24 | ... BK23: =BK13*Premissas!$B$24
A24: RECEITA TOTAL (R$) | B24: R$ | C24: 0 | D24: =D17+D18+D21+D22+D23 | E24: =E17+E18+E21+E22+E23 | F24: =F17+F18+F21+F22+F23 | G24: =G17+G18+G21+G22+G23 | H24: =H17+H18+H21+H22+H23 | I24: =I17+I18+I21+I22+I23 | J24: =J17+J18+J21+J22+J23 | K24: =K17+K18+K21+K22+K23 | ... BK24: =BK17+BK18+BK21+BK22+BK23
A26: ── CUSTOS ──
A27: Custo de infraestrutura variável (R$) | B27: R$ | C27: 0 | D27: =CEILING(D15/Premissas!$B$36,1)*Premissas!$B$35 | E27: =CEILING(E15/Premissas!$B$36,1)*Premissas!$B$35 | F27: =CEILING(F15/Premissas!$B$36,1)*Premissas!$B$35 | G27: =CEILING(G15/Premissas!$B$36,1)*Premissas!$B$35 | H27: =CEILING(H15/Premissas!$B$36,1)*Premissas!$B$35 | I27: =CEILING(I15/Premissas!$B$36,1)*Premissas!$B$35 | J27: =CEILING(J15/Premissas!$B$36,1)*Premissas!$B$35 | K27: =CEILING(K15/Premissas!$B$36,1)*Premissas!$B$35 | ... BK27: =CEILING(BK15/Premissas!$B$36,1)*Premissas!$B$35
A28: Custo de equipe (R$) | B28: R$ | C28: 0 | D28: =ROUNDUP(D13/Premissas!$B$29,0)*Premissas!$B$30 | E28: =ROUNDUP(E13/Premissas!$B$29,0)*Premissas!$B$30 | F28: =ROUNDUP(F13/Premissas!$B$29,0)*Premissas!$B$30 | G28: =ROUNDUP(G13/Premissas!$B$29,0)*Premissas!$B$30 | H28: =ROUNDUP(H13/Premissas!$B$29,0)*Premissas!$B$30 | I28: =ROUNDUP(I13/Premissas!$B$29,0)*Premissas!$B$30 | J28: =ROUNDUP(J13/Premissas!$B$29,0)*Premissas!$B$30 | K28: =ROUNDUP(K13/Premissas!$B$29,0)*Premissas!$B$30 | ... BK28: =ROUNDUP(BK13/Premissas!$B$29,0)*Premissas!$B$30
A29: CAC do mês — aquisição de novos cadastros (R$) | B29: R$ | C29: 0 | D29: =D6*Premissas!$B$27 | E29: =E6*Premissas!$B$27 | F29: =F6*Premissas!$B$27 | G29: =G6*Premissas!$B$27 | H29: =H6*Premissas!$B$27 | I29: =I6*Premissas!$B$27 | J29: =J6*Premissas!$B$27 | K29: =K6*Premissas!$B$27 | ... BK29: =BK6*Premissas!$B$27
A30: Custos fixos administrativos (R$) | B30: R$ | C30: 0 | D30: =Premissas!$B$31 | E30: =Premissas!$B$31 | F30: =Premissas!$B$31 | G30: =Premissas!$B$31 | H30: =Premissas!$B$31 | I30: =Premissas!$B$31 | J30: =Premissas!$B$31 | K30: =Premissas!$B$31 | ... BK30: =Premissas!$B$31
A31: Impostos — Simples Nacional (R$) | B31: R$ | C31: 0 | D31: =D24*Premissas!$B$32 | E31: =E24*Premissas!$B$32 | F31: =F24*Premissas!$B$32 | G31: =G24*Premissas!$B$32 | H31: =H24*Premissas!$B$32 | I31: =I24*Premissas!$B$32 | J31: =J24*Premissas!$B$32 | K31: =K24*Premissas!$B$32 | ... BK31: =BK24*Premissas!$B$32
A32: DESPESAS TOTAIS (R$) | B32: R$ | C32: 0 | D32: =D27+D28+D29+D30+D31 | E32: =E27+E28+E29+E30+E31 | F32: =F27+F28+F29+F30+F31 | G32: =G27+G28+G29+G30+G31 | H32: =H27+H28+H29+H30+H31 | I32: =I27+I28+I29+I30+I31 | J32: =J27+J28+J29+J30+J31 | K32: =K27+K28+K29+K30+K31 | ... BK32: =BK27+BK28+BK29+BK30+BK31
A34: ── RESULTADO ──
A35: LUCRO LÍQUIDO DO MÊS (R$) | B35: R$ | C35: 0 | D35: =D24-D32 | E35: =E24-E32 | F35: =F24-F32 | G35: =G24-G32 | H35: =H24-H32 | I35: =I24-I32 | J35: =J24-J32 | K35: =K24-K32 | ... BK35: =BK24-BK32
A36: CAIXA ACUMULADO (R$) | B36: R$ | C36: =Premissas!$B$33 | D36: =C36+D35 | E36: =D36+E35 | F36: =E36+F35 | G36: =F36+G35 | H36: =G36+H35 | I36: =H36+I35 | J36: =I36+J35 | K36: =J36+K35 | ... BK36: =BJ36+BK35

Sheet Realista
A1: Cenário Realista — Projeção Mês a Mês (Lançamento + 60 meses = 5 anos)
A2: Todas as células desta aba são fórmula. Premissas (azul) ficam só na aba 'Premissas'.
A3: Métrica | B3: Unid. | C3: Lança- mento | D3: Ano 1 | P3: Ano 2 | AB3: Ano 3 | AN3: Ano 4 | AZ3: Ano 5
A4: ── FUNIL DE USUÁRIOS ── | C4: 0 | D4: 1 | E4: 2 | F4: 3 | G4: 4 | H4: 5 | I4: 6 | J4: 7 | K4: 8 | L4: 9 | M4: 10 | N4: 11 | O4: 12 | P4: 13 | Q4: 14 | R4: 15 | S4: 16 | T4: 17 | U4: 18 | V4: 19 | W4: 20 | X4: 21 | Y4: 22 | Z4: 23 | AA4: 24 | AB4: 25 | AC4: 26 | AD4: 27 | AE4: 28 | AF4: 29 | AG4: 30 | AH4: 31 | AI4: 32 | AJ4: 33 | AK4: 34 | AL4: 35 | AM4: 36 | AN4: 37 | AO4: 38 | AP4: 39 | AQ4: 40 | AR4: 41 | AS4: 42 | AT4: 43 | AU4: 44 | AV4: 45 | AW4: 46 | AX4: 47 | AY4: 48 | AZ4: 49 | BA4: 50 | BB4: 51 | BC4: 52 | BD4: 53 | BE4: 54 | BF4: 55 | BG4: 56 | BH4: 57 | BI4: 58 | BJ4: 59 | BK4: 60
A6: Novos cadastros Node: Starter (qtd) | B6: qtd | C6: 0 | D6: =MIN(Premissas!$C$9,Premissas!$C$11) | E6: =MIN(D6*(1+Premissas!$C$10),Premissas!$C$11) | F6: =MIN(E6*(1+Premissas!$C$10),Premissas!$C$11) | G6: =MIN(F6*(1+Premissas!$C$10),Premissas!$C$11) | H6: =MIN(G6*(1+Premissas!$C$10),Premissas!$C$11) | I6: =MIN(H6*(1+Premissas!$C$10),Premissas!$C$11) | J6: =MIN(I6*(1+Premissas!$C$10),Premissas!$C$11) | K6: =MIN(J6*(1+Premissas!$C$10),Premissas!$C$11) | L6: =MIN(K6*(1+Premissas!$C$10),Premissas!$C$11) | ... BK6: =MIN(BJ6*(1+Premissas!$C$10),Premissas!$C$11)
A7: Convertidos Starter → Pago no mês (qtd) | B7: qtd | C7: 0 | D7: 0 | E7: =C6*Premissas!$C$12 | F7: =D6*Premissas!$C$12 | G7: =E6*Premissas!$C$12 | H7: =F6*Premissas!$C$12 | I7: =G6*Premissas!$C$12 | J7: =H6*Premissas!$C$12 | K7: =I6*Premissas!$C$12 | L7: =J6*Premissas!$C$12 | ... BK7: =BI6*Premissas!$C$12
A8: Node: Starter ativos (qtd) | B8: qtd | C8: 0 | D8: =C8*(1-Premissas!$C$14)+D6-D7 | E8: =D8*(1-Premissas!$C$14)+E6-E7 | F8: =E8*(1-Premissas!$C$14)+F6-F7 | G8: =F8*(1-Premissas!$C$14)+G6-G7 | H8: =G8*(1-Premissas!$C$14)+H6-H7 | I8: =H8*(1-Premissas!$C$14)+I6-I7 | J8: =I8*(1-Premissas!$C$14)+J6-J7 | K8: =J8*(1-Premissas!$C$14)+K6-K7 | ... BK8: =BJ8*(1-Premissas!$C$14)+BK6-BK7
A9: Novos pagantes Node: Pro no mês (qtd) | B9: qtd | C9: 0 | D9: =D7*Premissas!$C$13 | E9: =E7*Premissas!$C$13 | F9: =F7*Premissas!$C$13 | G9: =G7*Premissas!$C$13 | H9: =H7*Premissas!$C$13 | I9: =I7*Premissas!$C$13 | J9: =J7*Premissas!$C$13 | K9: =K7*Premissas!$C$13 | ... BK9: =BK7*Premissas!$C$13
A10: Novos pagantes Node: Institutional no mês (qtd) | B10: qtd | C10: 0 | D10: =D7*(1-Premissas!$C$13) | E10: =E7*(1-Premissas!$C$13) | F10: =F7*(1-Premissas!$C$13) | G10: =G7*(1-Premissas!$C$13) | H10: =H7*(1-Premissas!$C$13) | I10: =I7*(1-Premissas!$C$13) | J10: =J7*(1-Premissas!$C$13) | K10: =K7*(1-Premissas!$C$13) | ... BK10: =BK7*(1-Premissas!$C$13)
A11: Node: Pro ativos (qtd) | B11: qtd | C11: 0 | D11: =C11*(1-Premissas!$C$15)+D9 | E11: =D11*(1-Premissas!$C$15)+E9 | F11: =E11*(1-Premissas!$C$15)+F9 | G11: =F11*(1-Premissas!$C$15)+G9 | H11: =G11*(1-Premissas!$C$15)+H9 | I11: =H11*(1-Premissas!$C$15)+I9 | J11: =I11*(1-Premissas!$C$15)+J9 | K11: =J11*(1-Premissas!$C$15)+K9 | ... BK11: =BJ11*(1-Premissas!$C$15)+BK9
A12: Node: Institutional ativos (qtd) | B12: qtd | C12: 0 | D12: =C12*(1-Premissas!$C$15)+D10 | E12: =D12*(1-Premissas!$C$15)+E10 | F12: =E12*(1-Premissas!$C$15)+F10 | G12: =F12*(1-Premissas!$C$15)+G10 | H12: =G12*(1-Premissas!$C$15)+H10 | I12: =H12*(1-Premissas!$C$15)+I10 | J12: =I12*(1-Premissas!$C$15)+J10 | K12: =J12*(1-Premissas!$C$15)+K10 | ... BK12: =BJ12*(1-Premissas!$C$15)+BK10
A13: Total pagantes ativos — Pro + Institutional (qtd) | B13: qtd | C13: 0 | D13: =D11+D12 | E13: =E11+E12 | F13: =F11+F12 | G13: =G11+G12 | H13: =H11+H12 | I13: =I11+I12 | J13: =J11+J12 | K13: =K11+K12 | ... BK13: =BK11+BK12
A14: Total usuários ativos — Starter + pagantes (qtd) | B14: qtd | C14: 0 | D14: =D8+D13 | E14: =E8+E13 | F14: =F8+F13 | G14: =G8+G13 | H14: =H8+H13 | I14: =I8+I13 | J14: =J8+J13 | K14: =K8+K13 | ... BK14: =BK8+BK13
A15: Carga de GPU equivalente (usuários-mês) — pagantes + degustação Starter | D15: =D13+D6*(Premissas!$C$38/30) | E15: =E13+E6*(Premissas!$C$38/30) | F15: =F13+F6*(Premissas!$C$38/30) | G15: =G13+G6*(Premissas!$C$38/30) | H15: =H13+H6*(Premissas!$C$38/30) | I15: =I13+I6*(Premissas!$C$38/30) | J15: =J13+J6*(Premissas!$C$38/30) | K15: =K13+K6*(Premissas!$C$38/30) | ... BK15: =BK13+BK6*(Premissas!$C$38/30)
A16: ── RECEITA ──
A17: Receita mensalidade Node: Pro (R$) | B17: R$ | C17: 0 | D17: =D11*Premissas!$C$5 | E17: =E11*Premissas!$C$5 | F17: =F11*Premissas!$C$5 | G17: =G11*Premissas!$C$5 | H17: =H11*Premissas!$C$5 | I17: =I11*Premissas!$C$5 | J17: =J11*Premissas!$C$5 | K17: =K11*Premissas!$C$5 | ... BK17: =BK11*Premissas!$C$5
A18: Receita mensalidade Node: Institutional (R$) | B18: R$ | C18: 0 | D18: =D12*Premissas!$C$6 | E18: =E12*Premissas!$C$6 | F18: =F12*Premissas!$C$6 | G18: =G12*Premissas!$C$6 | H18: =H12*Premissas!$C$6 | I18: =I12*Premissas!$C$6 | J18: =J12*Premissas!$C$6 | K18: =K12*Premissas!$C$6 | ... BK18: =BK12*Premissas!$C$6
A19: Lotes negociados no mês — Pro+Institutional (lotes) | B19: lotes | C19: 0 | D19: =D13*Premissas!$C$18 | E19: =E13*Premissas!$C$18 | F19: =F13*Premissas!$C$18 | G19: =G13*Premissas!$C$18 | H19: =H13*Premissas!$C$18 | I19: =I13*Premissas!$C$18 | J19: =J13*Premissas!$C$18 | K19: =K13*Premissas!$C$18 | ... BK19: =BK13*Premissas!$C$18
A20: Lotes negociados no mês — Starter (lotes) | B20: lotes | C20: 0 | D20: =D6*Premissas!$C$19 | E20: =E6*Premissas!$C$19 | F20: =F6*Premissas!$C$19 | G20: =G6*Premissas!$C$19 | H20: =H6*Premissas!$C$19 | I20: =I6*Premissas!$C$19 | J20: =J6*Premissas!$C$19 | K20: =K6*Premissas!$C$19 | ... BK20: =BK6*Premissas!$C$19
A21: Receita comissão própria — só sobre volume Starter (R$) | B21: R$ | C21: 0 | D21: =(D19+D20)*Premissas!$C$22 | E21: =(E19+E20)*Premissas!$C$22 | F21: =(F19+F20)*Premissas!$C$22 | G21: =(G19+G20)*Premissas!$C$22 | H21: =(H19+H20)*Premissas!$C$22 | I21: =(I19+I20)*Premissas!$C$22 | J21: =(J19+J20)*Premissas!$C$22 | K21: =(K19+K20)*Premissas!$C$22 | ... BK21: =(BK19+BK20)*Premissas!$C$22
A22: Receita rebate IB — sobre todo o volume (R$) | B22: R$ | C22: 0 | D22: =(D19+D20)*Premissas!$C$23 | E22: =(E19+E20)*Premissas!$C$23 | F22: =(F19+F20)*Premissas!$C$23 | G22: =(G19+G20)*Premissas!$C$23 | H22: =(H19+H20)*Premissas!$C$23 | I22: =(I19+I20)*Premissas!$C$23 | J22: =(J19+J20)*Premissas!$C$23 | K22: =(K19+K20)*Premissas!$C$23 | ... BK22: =(BK19+BK20)*Premissas!$C$23
A23: Receita marketplace (R$) | B23: R$ | C23: 0 | D23: =D13*Premissas!$C$24 | E23: =E13*Premissas!$C$24 | F23: =F13*Premissas!$C$24 | G23: =G13*Premissas!$C$24 | H23: =H13*Premissas!$C$24 | I23: =I13*Premissas!$C$24 | J23: =J13*Premissas!$C$24 | K23: =K13*Premissas!$C$24 | ... BK23: =BK13*Premissas!$C$24
A24: RECEITA TOTAL (R$) | B24: R$ | C24: 0 | D24: =D17+D18+D21+D22+D23 | E24: =E17+E18+E21+E22+E23 | F24: =F17+F18+F21+F22+F23 | G24: =G17+G18+G21+G22+G23 | H24: =H17+H18+H21+H22+H23 | I24: =I17+I18+I21+I22+I23 | J24: =J17+J18+J21+J22+J23 | K24: =K17+K18+K21+K22+K23 | ... BK24: =BK17+BK18+BK21+BK22+BK23
A26: ── CUSTOS ──
A27: Custo de infraestrutura variável (R$) | B27: R$ | C27: 0 | D27: =CEILING(D15/Premissas!$C$36,1)*Premissas!$C$35 | E27: =CEILING(E15/Premissas!$C$36,1)*Premissas!$C$35 | F27: =CEILING(F15/Premissas!$C$36,1)*Premissas!$C$35 | G27: =CEILING(G15/Premissas!$C$36,1)*Premissas!$C$35 | H27: =CEILING(H15/Premissas!$C$36,1)*Premissas!$C$35 | I27: =CEILING(I15/Premissas!$C$36,1)*Premissas!$C$35 | J27: =CEILING(J15/Premissas!$C$36,1)*Premissas!$C$35 | K27: =CEILING(K15/Premissas!$C$36,1)*Premissas!$C$35 | ... BK27: =CEILING(BK15/Premissas!$C$36,1)*Premissas!$C$35
A28: Custo de equipe (R$) | B28: R$ | C28: 0 | D28: =ROUNDUP(D13/Premissas!$C$29,0)*Premissas!$C$30 | E28: =ROUNDUP(E13/Premissas!$C$29,0)*Premissas!$C$30 | F28: =ROUNDUP(F13/Premissas!$C$29,0)*Premissas!$C$30 | G28: =ROUNDUP(G13/Premissas!$C$29,0)*Premissas!$C$30 | H28: =ROUNDUP(H13/Premissas!$C$29,0)*Premissas!$C$30 | I28: =ROUNDUP(I13/Premissas!$C$29,0)*Premissas!$C$30 | J28: =ROUNDUP(J13/Premissas!$C$29,0)*Premissas!$C$30 | K28: =ROUNDUP(K13/Premissas!$C$29,0)*Premissas!$C$30 | ... BK28: =ROUNDUP(BK13/Premissas!$C$29,0)*Premissas!$C$30
A29: CAC do mês — aquisição de novos cadastros (R$) | B29: R$ | C29: 0 | D29: =D6*Premissas!$C$27 | E29: =E6*Premissas!$C$27 | F29: =F6*Premissas!$C$27 | G29: =G6*Premissas!$C$27 | H29: =H6*Premissas!$C$27 | I29: =I6*Premissas!$C$27 | J29: =J6*Premissas!$C$27 | K29: =K6*Premissas!$C$27 | ... BK29: =BK6*Premissas!$C$27
A30: Custos fixos administrativos (R$) | B30: R$ | C30: 0 | D30: =Premissas!$C$31 | E30: =Premissas!$C$31 | F30: =Premissas!$C$31 | G30: =Premissas!$C$31 | H30: =Premissas!$C$31 | I30: =Premissas!$C$31 | J30: =Premissas!$C$31 | K30: =Premissas!$C$31 | ... BK30: =Premissas!$C$31
A31: Impostos — Simples Nacional (R$) | B31: R$ | C31: 0 | D31: =D24*Premissas!$C$32 | E31: =E24*Premissas!$C$32 | F31: =F24*Premissas!$C$32 | G31: =G24*Premissas!$C$32 | H31: =H24*Premissas!$C$32 | I31: =I24*Premissas!$C$32 | J31: =J24*Premissas!$C$32 | K31: =K24*Premissas!$C$32 | ... BK31: =BK24*Premissas!$C$32
A32: DESPESAS TOTAIS (R$) | B32: R$ | C32: 0 | D32: =D27+D28+D29+D30+D31 | E32: =E27+E28+E29+E30+E31 | F32: =F27+F28+F29+F30+F31 | G32: =G27+G28+G29+G30+G31 | H32: =H27+H28+H29+H30+H31 | I32: =I27+I28+I29+I30+I31 | J32: =J27+J28+J29+J30+J31 | K32: =K27+K28+K29+K30+K31 | ... BK32: =BK27+BK28+BK29+BK30+BK31
A34: ── RESULTADO ──
A35: LUCRO LÍQUIDO DO MÊS (R$) | B35: R$ | C35: 0 | D35: =D24-D32 | E35: =E24-E32 | F35: =F24-F32 | G35: =G24-G32 | H35: =H24-H32 | I35: =I24-I32 | J35: =J24-J32 | K35: =K24-K32 | ... BK35: =BK24-BK32
A36: CAIXA ACUMULADO (R$) | B36: R$ | C36: =Premissas!$C$33 | D36: =C36+D35 | E36: =D36+E35 | F36: =E36+F35 | G36: =F36+G35 | H36: =G36+H35 | I36: =H36+I35 | J36: =I36+J35 | K36: =J36+K35 | ... BK36: =BJ36+BK35

Sheet Otimista
A1: Cenário Otimista — Projeção Mês a Mês (Lançamento + 60 meses = 5 anos)
A2: Todas as células desta aba são fórmula. Premissas (azul) ficam só na aba 'Premissas'.
A3: Métrica | B3: Unid. | C3: Lança- mento | D3: Ano 1 | P3: Ano 2 | AB3: Ano 3 | AN3: Ano 4 | AZ3: Ano 5
A4: ── FUNIL DE USUÁRIOS ── | C4: 0 | D4: 1 | E4: 2 | F4: 3 | G4: 4 | H4: 5 | I4: 6 | J4: 7 | K4: 8 | L4: 9 | M4: 10 | N4: 11 | O4: 12 | P4: 13 | Q4: 14 | R4: 15 | S4: 16 | T4: 17 | U4: 18 | V4: 19 | W4: 20 | X4: 21 | Y4: 22 | Z4: 23 | AA4: 24 | AB4: 25 | AC4: 26 | AD4: 27 | AE4: 28 | AF4: 29 | AG4: 30 | AH4: 31 | AI4: 32 | AJ4: 33 | AK4: 34 | AL4: 35 | AM4: 36 | AN4: 37 | AO4: 38 | AP4: 39 | AQ4: 40 | AR4: 41 | AS4: 42 | AT4: 43 | AU4: 44 | AV4: 45 | AW4: 46 | AX4: 47 | AY4: 48 | AZ4: 49 | BA4: 50 | BB4: 51 | BC4: 52 | BD4: 53 | BE4: 54 | BF4: 55 | BG4: 56 | BH4: 57 | BI4: 58 | BJ4: 59 | BK4: 60
A6: Novos cadastros Node: Starter (qtd) | B6: qtd | C6: 0 | D6: =MIN(Premissas!$D$9,Premissas!$D$11) | E6: =MIN(D6*(1+Premissas!$D$10),Premissas!$D$11) | F6: =MIN(E6*(1+Premissas!$D$10),Premissas!$D$11) | G6: =MIN(F6*(1+Premissas!$D$10),Premissas!$D$11) | H6: =MIN(G6*(1+Premissas!$D$10),Premissas!$D$11) | I6: =MIN(H6*(1+Premissas!$D$10),Premissas!$D$11) | J6: =MIN(I6*(1+Premissas!$D$10),Premissas!$D$11) | K6: =MIN(J6*(1+Premissas!$D$10),Premissas!$D$11) | L6: =MIN(K6*(1+Premissas!$D$10),Premissas!$D$11) | ... BK6: =MIN(BJ6*(1+Premissas!$D$10),Premissas!$D$11)
A7: Convertidos Starter → Pago no mês (qtd) | B7: qtd | C7: 0 | D7: 0 | E7: =C6*Premissas!$D$12 | F7: =D6*Premissas!$D$12 | G7: =E6*Premissas!$D$12 | H7: =F6*Premissas!$D$12 | I7: =G6*Premissas!$D$12 | J7: =H6*Premissas!$D$12 | K7: =I6*Premissas!$D$12 | L7: =J6*Premissas!$D$12 | ... BK7: =BI6*Premissas!$D$12
A8: Node: Starter ativos (qtd) | B8: qtd | C8: 0 | D8: =C8*(1-Premissas!$D$14)+D6-D7 | E8: =D8*(1-Premissas!$D$14)+E6-E7 | F8: =E8*(1-Premissas!$D$14)+F6-F7 | G8: =F8*(1-Premissas!$D$14)+G6-G7 | H8: =G8*(1-Premissas!$D$14)+H6-H7 | I8: =H8*(1-Premissas!$D$14)+I6-I7 | J8: =I8*(1-Premissas!$D$14)+J6-J7 | K8: =J8*(1-Premissas!$D$14)+K6-K7 | ... BK8: =BJ8*(1-Premissas!$D$14)+BK6-BK7
A9: Novos pagantes Node: Pro no mês (qtd) | B9: qtd | C9: 0 | D9: =D7*Premissas!$D$13 | E9: =E7*Premissas!$D$13 | F9: =F7*Premissas!$D$13 | G9: =G7*Premissas!$D$13 | H9: =H7*Premissas!$D$13 | I9: =I7*Premissas!$D$13 | J9: =J7*Premissas!$D$13 | K9: =K7*Premissas!$D$13 | ... BK9: =BK7*Premissas!$D$13
A10: Novos pagantes Node: Institutional no mês (qtd) | B10: qtd | C10: 0 | D10: =D7*(1-Premissas!$D$13) | E10: =E7*(1-Premissas!$D$13) | F10: =F7*(1-Premissas!$D$13) | G10: =G7*(1-Premissas!$D$13) | H10: =H7*(1-Premissas!$D$13) | I10: =I7*(1-Premissas!$D$13) | J10: =J7*(1-Premissas!$D$13) | K10: =K7*(1-Premissas!$D$13) | ... BK10: =BK7*(1-Premissas!$D$13)
A11: Node: Pro ativos (qtd) | B11: qtd | C11: 0 | D11: =C11*(1-Premissas!$D$15)+D9 | E11: =D11*(1-Premissas!$D$15)+E9 | F11: =E11*(1-Premissas!$D$15)+F9 | G11: =F11*(1-Premissas!$D$15)+G9 | H11: =G11*(1-Premissas!$D$15)+H9 | I11: =H11*(1-Premissas!$D$15)+I9 | J11: =I11*(1-Premissas!$D$15)+J9 | K11: =J11*(1-Premissas!$D$15)+K9 | ... BK11: =BJ11*(1-Premissas!$D$15)+BK9
A12: Node: Institutional ativos (qtd) | B12: qtd | C12: 0 | D12: =C12*(1-Premissas!$D$15)+D10 | E12: =D12*(1-Premissas!$D$15)+E10 | F12: =E12*(1-Premissas!$D$15)+F10 | G12: =F12*(1-Premissas!$D$15)+G10 | H12: =G12*(1-Premissas!$D$15)+H10 | I12: =H12*(1-Premissas!$D$15)+I10 | J12: =I12*(1-Premissas!$D$15)+J10 | K12: =J12*(1-Premissas!$D$15)+K10 | ... BK12: =BJ12*(1-Premissas!$D$15)+BK10
A13: Total pagantes ativos — Pro + Institutional (qtd) | B13: qtd | C13: 0 | D13: =D11+D12 | E13: =E11+E12 | F13: =F11+F12 | G13: =G11+G12 | H13: =H11+H12 | I13: =I11+I12 | J13: =J11+J12 | K13: =K11+K12 | ... BK13: =BK11+BK12
A14: Total usuários ativos — Starter + pagantes (qtd) | B14: qtd | C14: 0 | D14: =D8+D13 | E14: =E8+E13 | F14: =F8+F13 | G14: =G8+G13 | H14: =H8+H13 | I14: =I8+I13 | J14: =J8+J13 | K14: =K8+K13 | ... BK14: =BK8+BK13
A15: Carga de GPU equivalente (usuários-mês) — pagantes + degustação Starter | D15: =D13+D6*(Premissas!$D$38/30) | E15: =E13+E6*(Premissas!$D$38/30) | F15: =F13+F6*(Premissas!$D$38/30) | G15: =G13+G6*(Premissas!$D$38/30) | H15: =H13+H6*(Premissas!$D$38/30) | I15: =I13+I6*(Premissas!$D$38/30) | J15: =J13+J6*(Premissas!$D$38/30) | K15: =K13+K6*(Premissas!$D$38/30) | ... BK15: =BK13+BK6*(Premissas!$D$38/30)
A16: ── RECEITA ──
A17: Receita mensalidade Node: Pro (R$) | B17: R$ | C17: 0 | D17: =D11*Premissas!$D$5 | E17: =E11*Premissas!$D$5 | F17: =F11*Premissas!$D$5 | G17: =G11*Premissas!$D$5 | H17: =H11*Premissas!$D$5 | I17: =I11*Premissas!$D$5 | J17: =J11*Premissas!$D$5 | K17: =K11*Premissas!$D$5 | ... BK17: =BK11*Premissas!$D$5
A18: Receita mensalidade Node: Institutional (R$) | B18: R$ | C18: 0 | D18: =D12*Premissas!$D$6 | E18: =E12*Premissas!$D$6 | F18: =F12*Premissas!$D$6 | G18: =G12*Premissas!$D$6 | H18: =H12*Premissas!$D$6 | I18: =I12*Premissas!$D$6 | J18: =J12*Premissas!$D$6 | K18: =K12*Premissas!$D$6 | ... BK18: =BK12*Premissas!$D$6
A19: Lotes negociados no mês — Pro+Institutional (lotes) | B19: lotes | C19: 0 | D19: =D13*Premissas!$D$18 | E19: =E13*Premissas!$D$18 | F19: =F13*Premissas!$D$18 | G19: =G13*Premissas!$D$18 | H19: =H13*Premissas!$D$18 | I19: =I13*Premissas!$D$18 | J19: =J13*Premissas!$D$18 | K19: =K13*Premissas!$D$18 | ... BK19: =BK13*Premissas!$D$18
A20: Lotes negociados no mês — Starter (lotes) | B20: lotes | C20: 0 | D20: =D6*Premissas!$D$19 | E20: =E6*Premissas!$D$19 | F20: =F6*Premissas!$D$19 | G20: =G6*Premissas!$D$19 | H20: =H6*Premissas!$D$19 | I20: =I6*Premissas!$D$19 | J20: =J6*Premissas!$D$19 | K20: =K6*Premissas!$D$19 | ... BK20: =BK6*Premissas!$D$19
A21: Receita comissão própria — só sobre volume Starter (R$) | B21: R$ | C21: 0 | D21: =(D19+D20)*Premissas!$D$22 | E21: =(E19+E20)*Premissas!$D$22 | F21: =(F19+F20)*Premissas!$D$22 | G21: =(G19+G20)*Premissas!$D$22 | H21: =(H19+H20)*Premissas!$D$22 | I21: =(I19+I20)*Premissas!$D$22 | J21: =(J19+J20)*Premissas!$D$22 | K21: =(K19+K20)*Premissas!$D$22 | ... BK21: =(BK19+BK20)*Premissas!$D$22
A22: Receita rebate IB — sobre todo o volume (R$) | B22: R$ | C22: 0 | D22: =(D19+D20)*Premissas!$D$23 | E22: =(E19+E20)*Premissas!$D$23 | F22: =(F19+F20)*Premissas!$D$23 | G22: =(G19+G20)*Premissas!$D$23 | H22: =(H19+H20)*Premissas!$D$23 | I22: =(I19+I20)*Premissas!$D$23 | J22: =(J19+J20)*Premissas!$D$23 | K22: =(K19+K20)*Premissas!$D$23 | ... BK22: =(BK19+BK20)*Premissas!$D$23
A23: Receita marketplace (R$) | B23: R$ | C23: 0 | D23: =D13*Premissas!$D$24 | E23: =E13*Premissas!$D$24 | F23: =F13*Premissas!$D$24 | G23: =G13*Premissas!$D$24 | H23: =H13*Premissas!$D$24 | I23: =I13*Premissas!$D$24 | J23: =J13*Premissas!$D$24 | K23: =K13*Premissas!$D$24 | ... BK23: =BK13*Premissas!$D$24
A24: RECEITA TOTAL (R$) | B24: R$ | C24: 0 | D24: =D17+D18+D21+D22+D23 | E24: =E17+E18+E21+E22+E23 | F24: =F17+F18+F21+F22+F23 | G24: =G17+G18+G21+G22+G23 | H24: =H17+H18+H21+H22+H23 | I24: =I17+I18+I21+I22+I23 | J24: =J17+J18+J21+J22+J23 | K24: =K17+K18+K21+K22+K23 | ... BK24: =BK17+BK18+BK21+BK22+BK23
A26: ── CUSTOS ──
A27: Custo de infraestrutura variável (R$) | B27: R$ | C27: 0 | D27: =CEILING(D15/Premissas!$D$36,1)*Premissas!$D$35 | E27: =CEILING(E15/Premissas!$D$36,1)*Premissas!$D$35 | F27: =CEILING(F15/Premissas!$D$36,1)*Premissas!$D$35 | G27: =CEILING(G15/Premissas!$D$36,1)*Premissas!$D$35 | H27: =CEILING(H15/Premissas!$D$36,1)*Premissas!$D$35 | I27: =CEILING(I15/Premissas!$D$36,1)*Premissas!$D$35 | J27: =CEILING(J15/Premissas!$D$36,1)*Premissas!$D$35 | K27: =CEILING(K15/Premissas!$D$36,1)*Premissas!$D$35 | ... BK27: =CEILING(BK15/Premissas!$D$36,1)*Premissas!$D$35
A28: Custo de equipe (R$) | B28: R$ | C28: 0 | D28: =ROUNDUP(D13/Premissas!$D$29,0)*Premissas!$D$30 | E28: =ROUNDUP(E13/Premissas!$D$29,0)*Premissas!$D$30 | F28: =ROUNDUP(F13/Premissas!$D$29,0)*Premissas!$D$30 | G28: =ROUNDUP(G13/Premissas!$D$29,0)*Premissas!$D$30 | H28: =ROUNDUP(H13/Premissas!$D$29,0)*Premissas!$D$30 | I28: =ROUNDUP(I13/Premissas!$D$29,0)*Premissas!$D$30 | J28: =ROUNDUP(J13/Premissas!$D$29,0)*Premissas!$D$30 | K28: =ROUNDUP(K13/Premissas!$D$29,0)*Premissas!$D$30 | ... BK28: =ROUNDUP(BK13/Premissas!$D$29,0)*Premissas!$D$30
A29: CAC do mês — aquisição de novos cadastros (R$) | B29: R$ | C29: 0 | D29: =D6*Premissas!$D$27 | E29: =E6*Premissas!$D$27 | F29: =F6*Premissas!$D$27 | G29: =G6*Premissas!$D$27 | H29: =H6*Premissas!$D$27 | I29: =I6*Premissas!$D$27 | J29: =J6*Premissas!$D$27 | K29: =K6*Premissas!$D$27 | ... BK29: =BK6*Premissas!$D$27
A30: Custos fixos administrativos (R$) | B30: R$ | C30: 0 | D30: =Premissas!$D$31 | E30: =Premissas!$D$31 | F30: =Premissas!$D$31 | G30: =Premissas!$D$31 | H30: =Premissas!$D$31 | I30: =Premissas!$D$31 | J30: =Premissas!$D$31 | K30: =Premissas!$D$31 | ... BK30: =Premissas!$D$31
A31: Impostos — Simples Nacional (R$) | B31: R$ | C31: 0 | D31: =D24*Premissas!$D$32 | E31: =E24*Premissas!$D$32 | F31: =F24*Premissas!$D$32 | G31: =G24*Premissas!$D$32 | H31: =H24*Premissas!$D$32 | I31: =I24*Premissas!$D$32 | J31: =J24*Premissas!$D$32 | K31: =K24*Premissas!$D$32 | ... BK31: =BK24*Premissas!$D$32
A32: DESPESAS TOTAIS (R$) | B32: R$ | C32: 0 | D32: =D27+D28+D29+D30+D31 | E32: =E27+E28+E29+E30+E31 | F32: =F27+F28+F29+F30+F31 | G32: =G27+G28+G29+G30+G31 | H32: =H27+H28+H29+H30+H31 | I32: =I27+I28+I29+I30+I31 | J32: =J27+J28+J29+J30+J31 | K32: =K27+K28+K29+K30+K31 | ... BK32: =BK27+BK28+BK29+BK30+BK31
A34: ── RESULTADO ──
A35: LUCRO LÍQUIDO DO MÊS (R$) | B35: R$ | C35: 0 | D35: =D24-D32 | E35: =E24-E32 | F35: =F24-F32 | G35: =G24-G32 | H35: =H24-H32 | I35: =I24-I32 | J35: =J24-J32 | K35: =K24-K32 | ... BK35: =BK24-BK32
A36: CAIXA ACUMULADO (R$) | B36: R$ | C36: =Premissas!$D$33 | D36: =C36+D35 | E36: =D36+E35 | F36: =E36+F35 | G36: =F36+G35 | H36: =G36+H35 | I36: =H36+I35 | J36: =I36+J35 | K36: =J36+K35 | ... BK36: =BJ36+BK35

Sheet Resumo Anual
A1: Resumo Anual — Ano 1 a Ano 5, os 3 cenários lado a lado
A3: Métrica | B3: Pessimista Ano 1 | C3: Pessimista Ano 2 | D3: Pessimista Ano 3 | E3: Pessimista Ano 4 | F3: Pessimista Ano 5 | H3: Realista Ano 1 | I3: Realista Ano 2 | J3: Realista Ano 3 | K3: Realista Ano 4 | L3: Realista Ano 5 | N3: Otimista Ano 1 | O3: Otimista Ano 2 | P3: Otimista Ano 3 | Q3: Otimista Ano 4 | R3: Otimista Ano 5
A4: Novos cadastros Starter no ano (qtd) | B4: =SUM(Pessimista!D6:O6) | C4: =SUM(Pessimista!P6:AA6) | D4: =SUM(Pessimista!AB6:AM6) | E4: =SUM(Pessimista!AN6:AY6) | F4: =SUM(Pessimista!AZ6:BK6) | H4: =SUM(Realista!D6:O6) | I4: =SUM(Realista!P6:AA6) | J4: =SUM(Realista!AB6:AM6) | K4: =SUM(Realista!AN6:AY6) | L4: =SUM(Realista!AZ6:BK6) | N4: =SUM(Otimista!D6:O6) | O4: =SUM(Otimista!P6:AA6) | P4: =SUM(Otimista!AB6:AM6) | Q4: =SUM(Otimista!AN6:AY6) | R4: =SUM(Otimista!AZ6:BK6)
A5: Pagantes ativos no fim do ano — Pro+Institutional (qtd) | B5: =Pessimista!O13 | C5: =Pessimista!AA13 | D5: =Pessimista!AM13 | E5: =Pessimista!AY13 | F5: =Pessimista!BK13 | H5: =Realista!O13 | I5: =Realista!AA13 | J5: =Realista!AM13 | K5: =Realista!AY13 | L5: =Realista!BK13 | N5: =Otimista!O13 | O5: =Otimista!AA13 | P5: =Otimista!AM13 | Q5: =Otimista!AY13 | R5: =Otimista!BK13
A6: Usuários ativos no fim do ano — total (qtd) | B6: =Pessimista!O14 | C6: =Pessimista!AA14 | D6: =Pessimista!AM14 | E6: =Pessimista!AY14 | F6: =Pessimista!BK14 | H6: =Realista!O14 | I6: =Realista!AA14 | J6: =Realista!AM14 | K6: =Realista!AY14 | L6: =Realista!BK14 | N6: =Otimista!O14 | O6: =Otimista!AA14 | P6: =Otimista!AM14 | Q6: =Otimista!AY14 | R6: =Otimista!BK14
A7: RECEITA TOTAL no ano (R$) | B7: =SUM(Pessimista!D24:O24) | C7: =SUM(Pessimista!P24:AA24) | D7: =SUM(Pessimista!AB24:AM24) | E7: =SUM(Pessimista!AN24:AY24) | F7: =SUM(Pessimista!AZ24:BK24) | H7: =SUM(Realista!D24:O24) | I7: =SUM(Realista!P24:AA24) | J7: =SUM(Realista!AB24:AM24) | K7: =SUM(Realista!AN24:AY24) | L7: =SUM(Realista!AZ24:BK24) | N7: =SUM(Otimista!D24:O24) | O7: =SUM(Otimista!P24:AA24) | P7: =SUM(Otimista!AB24:AM24) | Q7: =SUM(Otimista!AN24:AY24) | R7: =SUM(Otimista!AZ24:BK24)
A8: DESPESAS TOTAIS no ano (R$) | B8: =SUM(Pessimista!D32:O32) | C8: =SUM(Pessimista!P32:AA32) | D8: =SUM(Pessimista!AB32:AM32) | E8: =SUM(Pessimista!AN32:AY32) | F8: =SUM(Pessimista!AZ32:BK32) | H8: =SUM(Realista!D32:O32) | I8: =SUM(Realista!P32:AA32) | J8: =SUM(Realista!AB32:AM32) | K8: =SUM(Realista!AN32:AY32) | L8: =SUM(Realista!AZ32:BK32) | N8: =SUM(Otimista!D32:O32) | O8: =SUM(Otimista!P32:AA32) | P8: =SUM(Otimista!AB32:AM32) | Q8: =SUM(Otimista!AN32:AY32) | R8: =SUM(Otimista!AZ32:BK32)
A9: LUCRO LÍQUIDO do ano (R$) | B9: =SUM(Pessimista!D35:O35) | C9: =SUM(Pessimista!P35:AA35) | D9: =SUM(Pessimista!AB35:AM35) | E9: =SUM(Pessimista!AN35:AY35) | F9: =SUM(Pessimista!AZ35:BK35) | H9: =SUM(Realista!D35:O35) | I9: =SUM(Realista!P35:AA35) | J9: =SUM(Realista!AB35:AM35) | K9: =SUM(Realista!AN35:AY35) | L9: =SUM(Realista!AZ35:BK35) | N9: =SUM(Otimista!D35:O35) | O9: =SUM(Otimista!P35:AA35) | P9: =SUM(Otimista!AB35:AM35) | Q9: =SUM(Otimista!AN35:AY35) | R9: =SUM(Otimista!AZ35:BK35)
A10: CAIXA ACUMULADO no fim do ano (R$) | B10: =Pessimista!O36 | C10: =Pessimista!AA36 | D10: =Pessimista!AM36 | E10: =Pessimista!AY36 | F10: =Pessimista!BK36 | H10: =Realista!O36 | I10: =Realista!AA36 | J10: =Realista!AM36 | K10: =Realista!AY36 | L10: =Realista!BK36 | N10: =Otimista!O36 | O10: =Otimista!AA36 | P10: =Otimista!AM36 | Q10: =Otimista!AY36 | R10: =Otimista!BK36
A13: Comparativo — Total 5 anos (soma Ano1..Ano5 de faturamento/lucro; caixa e pagantes = fim do Ano 5)
A14: Métrica | B14: Pessimista | C14: Realista | D14: Otimista
A15: Faturamento total 5 anos (R$) | B15: =SUM(Pessimista!D24:BK24) | C15: =SUM(Realista!D24:BK24) | D15: =SUM(Otimista!D24:BK24)
A16: Despesas totais 5 anos (R$) | B16: =SUM(Pessimista!D32:BK32) | C16: =SUM(Realista!D32:BK32) | D16: =SUM(Otimista!D32:BK32)
A17: Lucro líquido total 5 anos (R$) | B17: =SUM(Pessimista!D35:BK35) | C17: =SUM(Realista!D35:BK35) | D17: =SUM(Otimista!D35:BK35)
A18: Caixa acumulado — fim do Ano 5 (R$) | B18: =Pessimista!BK36 | C18: =Realista!BK36 | D18: =Otimista!BK36
A19: Pagantes ativos — fim do Ano 5 (qtd) | B19: =Pessimista!BK13 | C19: =Realista!BK13 | D19: =Otimista!BK13
A20: Usuários ativos totais — fim do Ano 5 (qtd) | B20: =Pessimista!BK14 | C20: =Realista!BK14 | D20: =Otimista!BK14
A21: 1º mês com lucro líquido positivo | B21: =IFERROR(INDEX(Pessimista!D4:BK4,MATCH(TRUE(),INDEX(Pessimista!D35:BK35>0,0),0)),"Nunca no período") | C21: =IFERROR(INDEX(Realista!D4:BK4,MATCH(TRUE(),INDEX(Realista!D35:BK35>0,0),0)),"Nunca no período") | D21: =IFERROR(INDEX(Otimista!D4:BK4,MATCH(TRUE(),INDEX(Otimista!D35:BK35>0,0),0)),"Nunca no período")

Sheet Comissionamento
A1: Modelo de Comissionamento — Proposta Realinhada com Prática de Mercado
A3: Decisão implementada neste modelo
A4: DECISÃO (2026-08-10): comissão própria da plataforma cobrada sobre TODO o volume operado — Node: Starter, Node: Pro e Node: Institutional, sem diferenciação por tier. Modelado na aba Premissas, linha 'Comissão própria por lote', mesmo valor nos 3 cenários (R$30/lote ≈ US$6/lote) por ser política de preço, não projeção de crescimento.
A6: Base de mercado do valor (US$6/lote)
A7: US$6/lote padrão (US$0,06 por 0,01 lote) — pesquisa original do plano de 11/07/2026 (PLANEJAMENTO-LANCAMENTO-NEURAL-DAY-TRADER.md §3), ancorada em comissões ECN cTrader (US$4-8/lote, fontes: ForexBrokers.com, FP Markets) e ~15-20% abaixo do que a Infinox cobra na própria conta ECN (US$7-7,50/lote). Isso é o valor que MERCADO pratica pra uma plataforma que intermedia execução — não é um número inventado.
A9: Rebate IB — a segunda fonte, invisível ao trader
A10: Rebate IB (Introducing Broker) é uma fonte SEPARADA de receita, paga pela CORRETORA — não pelo trader — sobre o mesmo volume. A Infinox Partners paga até US$20/lote de rebate IB, negociável por instrumento/volume. O modelo usa R$15/25/35 por lote (pess/real/otim), convertido de ~US$4/6/8, que é o intervalo TÍPICO de mercado pra parceiros novos sem volume negociado ainda — não o teto de US$20 (isso exigiria volume/negociação que a plataforma não tem no lançamento).
A12: ⚠️ ALERTA que já existia no projeto — mantido de propósito, não removido
A13: Comissão própria (US$6/lote) + custo de execução na corretora (spread/comissão ECN, US$7-7,50/lote na Infinox) = custo empilhado de ~US$13/lote pro trader, quase 2x uma conta ECN pura sem intermediário. O plano de 11/07 já registrava esse alerta e recomendava ZERAR a comissão própria, vivendo só de mensalidade + rebate (que não tem essa fricção — quem paga é a corretora). A decisão desta sessão (cobrar em todos os tiers) reabre esse risco de propósito — registrado aqui pra ficar visível, não escondido.
A15: Recomendações de acompanhamento (não implementadas — decisão do Cleber)
A16: 1) Monitorar churn de usuários de alto volume (heavy traders) especificamente — são os mais sensíveis a esse custo empilhado e os que mais geram receita por lote; perder esse segmento por causa da comissão própria custaria caro. 2) Testar a alternativa 'zerar comissão própria' trocando a célula da aba Premissas pra R$0 e comparando o Lucro Líquido Total 5 anos na aba Resumo Anual — a comissão própria é só ~13% da receita projetada no plano original (mensalidade 64-78%, rebate 8-19%), então o modelo é sensível o suficiente pra esse teste valer a pena antes do lançamento público. 3) Se mantida em todos os tiers, considerar comunicar isso claramente na landing/termos — cobrar comissão sem transparência é o tipo de prática que gera reclamação e atrito com CVM (ver PLANEJAMENTO-LANCAMENTO §6, riscos jurídicos já mapeados).
A18: Fontes
... A39: 1) Usar o Ano 1 como gate de decisão: se os primeiros meses reais de conversão/churn/CAC vierem piores que o Realista ajustado (ex: conversão real < 6-7%, CAC real > R$150), isso é sinal precoce de que a operação está trilhando o caminho do Pessimista — cortar gasto de aquisição cedo em vez de escalar. 2) Rastrear as 3 métricas do gatilho (conversão Starter→Pago, CAC efetivo, churn mensal pago) desde o dia 1 do lançamento, comparando contra as 3 colunas da aba Premissas mês a mês — não esperar o Ano 1 fechar pra descobrir em qual cenário a operação real está.

Sheet Sugestões de Crescimento
A1: Sugestões para Crescimento Exponencial e Lucratividade
A2: Alavancas concretas — cada uma testável mudando uma célula azul na aba Premissas e olhando o impacto na aba Resumo Anual. Nenhuma delas foi incorporada como premissa numérica automática (a não ser que citado abaixo) — são recomendações pra decisão do Cleber.
A4: 1) A alavanca #1 é a conversão Starter→Pago, não o preço
A5: O maior alavanca do modelo não é preço nem comissão — é a TAXA DE CONVERSÃO Starter→Pago (linha amarela da aba Premissas). Ela é a única premissa que multiplica TODAS as fontes de receita ao mesmo tempo (mensalidade, comissão, rebate, marketplace todas dependem de quantos pagantes existem). Teste: suba a conversão realista de 6% pra 9% na aba Premissas e compare o Lucro Líquido Total 5 anos — o efeito composto ao longo de 60 meses é maior que qualquer ajuste isolado de preço.
A7: 2) Conversão orientada por gatilho de produto, não por tempo
A8: O modelo assume conversão em 2 meses e uma taxa única — na prática, ativação recorrente costuma vir de gatilhos: (a) o Starter recebe um sinal validado que teria sido lucrativo e não pôde agir automático (prompt nativo 'ative o Pro pra isso não acontecer de novo' no momento exato da dor); (b) sequência de erro de execução manual (o trader perdeu o timing) — mesmo gatilho; (c) e-mail/push depois de N dias de uso ativo do Starter (engajamento = sinal de prontidão pra pagar). Isso não muda a fórmula do modelo, muda a taxa de conversão real que ele deveria assumir — vale instrumentar esses gatilhos desde o dia 1 do lançamento pra medir, não estimar, a conversão real o quanto antes.
A10: 3) Faturamento anual anexo (upsell de caixa, não modelado ainda)
A11: Institutional (R$399) tem o selo 'Recommended' na landing (translations.ts) mas o modelo assume mix conservador (55-90% Pro conforme cenário). Testar: campanha de billing anual com desconto (ex: R$399×12×0,83 ≈ R$3.970/ano, 'pague 10, leve 12') aumenta caixa antecipado (reduz o menor-caixa-do-período, um dos furos já mapeados no plano de 11/07) E reduz churn mensal medido (quem já pagou o ano não cancela por impulso). Não modelado nesta versão — precisa de uma linha nova de premissa '% de assinantes em plano anual' pra entrar na planilha.
A13: 4) Syndicate Core como canal B2B separado — a real fonte de crescimento não-linear
A14: Syndicate Core (sob medida) não tem preço público e não entra na receita recorrente do modelo — mas é onde a curva pode virar de fato exponencial: 1 contrato de mesa proprietária/fundo pequeno vale potencialmente dezenas de assinaturas Institutional, com CAC quase zero (é decisão de negociação B2B, não tráfego pago) e sem o custo de servir milhares de usuários de varejo. Vale rastrear negociações Syndicate como uma linha separada de pipeline (fora da planilha de varejo) desde já, mesmo pré-lançamento — não force esse número dentro do modelo de varejo, ele tem uma dinâmica de venda completamente diferente (ciclo longo, ticket alto, poucos clientes).
A16: 5) Reduzir CAC via comunidade/indicação em vez de só mídia paga
A17: CAC de aquisição paga em trading de varejo é caro (R$180-260/cadastro no modelo, já alto) e o setor tem churn естrutural alto (§4 furo #3 do plano de 11/07: 'vida média de 3-6 meses'). Canais de CAC baixo pro nicho: (a) comunidade de trading (Discord/Telegram) com conteúdo educacional gratuito — constrói confiança antes da conversão, historicamente CAC 3-5x menor que ads pagos nesse vertical; (b) programa de indicação entre usuários Pro/Institutional (cashback de 1 mês de mensalidade por indicado convertido) — CAC vira quase-zero e o indicador já é um usuário retido, reforça permanência; (c) parceria com educadores/influenciadores de trading que já têm audiência (revenue share ou CPA, não salário fixo) — reduz risco de CAC afundado se o canal não performar.
... A23: Nada nesta aba assume que forçar mais entradas da IA aumenta receita — o projeto já mediu (CLAUDE.md, taxa base 2026-08-05) que edge ≈ 0 pra sinal técnico clássico, então mais trade = mais custo esperado pro usuário, não mais lucro pra ninguém. As alavancas de crescimento aqui são todas de PRODUTO/GTM (conversão, retenção, canal B2B, CAC), nunca de operar mais sem edge — isso mantém o modelo financeiro consistente com a disciplina técnica que o resto do projeto já adota.

Sheet Bootstrap
A1: Cenário Bootstrap — Projeção Mês a Mês (Lançamento + 60 meses = 5 anos) — sem CAC pago
A2: Todas as células desta aba são fórmula. Premissas (azul) ficam só na aba 'Premissas'.
A3: Métrica | B3: Unid. | C3: Lança- mento | D3: Ano 1 | P3: Ano 2 | AB3: Ano 3 | AN3: Ano 4 | AZ3: Ano 5
A4: ── FUNIL DE USUÁRIOS ── | C4: 0 | D4: 1 | E4: 2 | F4: 3 | G4: 4 | H4: 5 | I4: 6 | J4: 7 | K4: 8 | L4: 9 | M4: 10 | N4: 11 | O4: 12 | P4: 13 | Q4: 14 | R4: 15 | S4: 16 | T4: 17 | U4: 18 | V4: 19 | W4: 20 | X4: 21 | Y4: 22 | Z4: 23 | AA4: 24 | AB4: 25 | AC4: 26 | AD4: 27 | AE4: 28 | AF4: 29 | AG4: 30 | AH4: 31 | AI4: 32 | AJ4: 33 | AK4: 34 | AL4: 35 | AM4: 36 | AN4: 37 | AO4: 38 | AP4: 39 | AQ4: 40 | AR4: 41 | AS4: 42 | AT4: 43 | AU4: 44 | AV4: 45 | AW4: 46 | AX4: 47 | AY4: 48 | AZ4: 49 | BA4: 50 | BB4: 51 | BC4: 52 | BD4: 53 | BE4: 54 | BF4: 55 | BG4: 56 | BH4: 57 | BI4: 58 | BJ4: 59 | BK4: 60
A6: Novos cadastros Node: Starter (qtd) | B6: qtd | C6: 0 | D6: =MIN(Premissas!$F$9,Premissas!$F$11) | E6: =MIN(D6*(1+Premissas!$F$10),Premissas!$F$11) | F6: =MIN(E6*(1+Premissas!$F$10),Premissas!$F$11) | G6: =MIN(F6*(1+Premissas!$F$10),Premissas!$F$11) | H6: =MIN(G6*(1+Premissas!$F$10),Premissas!$F$11) | I6: =MIN(H6*(1+Premissas!$F$10),Premissas!$F$11) | J6: =MIN(I6*(1+Premissas!$F$10),Premissas!$F$11) | K6: =MIN(J6*(1+Premissas!$F$10),Premissas!$F$11) | L6: =MIN(K6*(1+Premissas!$F$10),Premissas!$F$11) | ... BK6: =MIN(BJ6*(1+Premissas!$F$10),Premissas!$F$11)
A7: Convertidos Starter → Pago no mês (qtd) | B7: qtd | C7: 0 | D7: 0 | E7: =C6*Premissas!$F$12 | F7: =D6*Premissas!$F$12 | G7: =E6*Premissas!$F$12 | H7: =F6*Premissas!$F$12 | I7: =G6*Premissas!$F$12 | J7: =H6*Premissas!$F$12 | K7: =I6*Premissas!$F$12 | L7: =J6*Premissas!$F$12 | ... BK7: =BI6*Premissas!$F$12
